Workbook

Sheet Overview
A1: Brick Pellet Production Overview
A5: Variables | B5: Clay | C5: Treatment | D5: Treatment | E5: Ash | F5: Treatment | G5: Treatment | H5: Firing temp [C]
B6: Ys (#0250) | C6: Dried 6 days 50 C | D6: Crushed <500mum | E6: SSA-P1-Raw (#0262) | F6: Dried 1 day 105C | G6: Mill 10 sec | H6: 1020
B7: Rs (#0252) | C7: Dried 6 days 50 C | D7: Crushed <500mum | E7: SSA-P1-ED (Pilot-8) | F7: Dried 1 day 105C | G7: Mill 10 sec | H7: 1030
C8: Dried 6 days 50 C | D8: Crushed <500mum | E8: SSA-P2-Raw (#0263) | F8: Dried 1 day 105C | G8: Mill 10 sec | H8: 1050
C9: Dried 6 days 50 C | D9: Crushed <5mum | E9: SSA-P2-ED (Pilot-10) | F9: Dried 1 day 105C | G9: Mill 10 sec
E10: SSA-P2-A2P (#0179) | F10: Dried 1 day 105C | G10: Mill 10 sec
A12: Mix order
A13: 1 | B13: Name | C13: Name | D13: Clay | E13: SSA | F13: Ash Treatment | G13: Temp [C] | H13: Annotation
B14: =CONCATENATE(,D14,"-",E14,"-",G14,) -> Y-Ref-1020 | C14: =CONCATENATE(,D14,"-",E14) -> Y-Ref | D14: Y | E14: Ref | G14: 1020
B15: =CONCATENATE(,D15,"-",E15,"-",G15,) -> Y-Ref-1030 | C15: =CONCATENATE(,D15,"-",E15) -> Y-Ref | D15: Y | E15: Ref | G15: 1030
B16: =CONCATENATE(,D16,"-",E16,"-",G16,) -> Y-Ref-1030 | C16: =CONCATENATE(,D16,"-",E16) -> Y-Ref | D16: Y | E16: Ref | G16: 1030
B17: =CONCATENATE(,D17,"-",E17,"-",F17,"-",G17,) -> Y-P1-Raw-1020 | C17: =CONCATENATE(,D17,"-",E17,"-",F17,) -> Y-P1-Raw | D17: Y | E17: P1 | F17: Raw | G17: =H$6 -> 1020
B18: =CONCATENATE(,D18,"-",E18,"-",F18,"-",G18,) -> Y-P1-Raw-1030 | C18: =CONCATENATE(,D18,"-",E18,"-",F18,) -> Y-P1-Raw | D18: Y | E18: P1 | F18: Raw | G18: =H$7 -> 1030
B19: =CONCATENATE(,D19,"-",E19,"-",F19,"-",G19,) -> Y-P1-Raw-1050 | C19: =CONCATENATE(,D19,"-",E19,"-",F19,) -> Y-P1-Raw | D19: Y | E19: P1 | F19: Raw | G19: =H$8 -> 1050
B20: =CONCATENATE(,D20,"-",E20,"-",F20,"-",G20,) -> Y-P1-ED-1020 | C20: =CONCATENATE(,D20,"-",E20,"-",F20,) -> Y-P1-ED | D20: Y | E20: P1 | F20: ED | G20: =H$6 -> 1020
B21: =CONCATENATE(,D21,"-",E21,"-",F21,"-",G21,) -> Y-P1-ED-1030 | C21: =CONCATENATE(,D21,"-",E21,"-",F21,) -> Y-P1-ED | D21: Y | E21: P1 | F21: ED | G21: =H$7 -> 1030
B22: =CONCATENATE(,D22,"-",E22,"-",F22,"-",G22,) -> Y-P1-ED-1050 | C22: =CONCATENATE(,D22,"-",E22,"-",F22,) -> Y-P1-ED | D22: Y | E22: P1 | F22: ED | G22: =H$8 -> 1050
B23: =CONCATENATE(,D23,"-",E23,"-",F23,"-",G23,) -> Y-P2-Raw-1020 | C23: =CONCATENATE(,D23,"-",E23,"-",F23,) -> Y-P2-Raw | D23: Y | E23: P2 | F23: Raw | G23: =H$6 -> 1020
B24: =CONCATENATE(,D24,"-",E24,"-",F24,"-",G24,) -> Y-P2-Raw-1030 | C24: =CONCATENATE(,D24,"-",E24,"-",F24,) -> Y-P2-Raw | D24: Y | E24: P2 | F24: Raw | G24: =H$7 -> 1030
B25: =CONCATENATE(,D25,"-",E25,"-",F25,"-",G25,) -> Y-P2-Raw-1050 | C25: =CONCATENATE(,D25,"-",E25,"-",F25,) -> Y-P2-Raw | D25: Y | E25: P2 | F25: Raw | G25: =H$8 -> 1050
B26: =CONCATENATE(,D26,"-",E26,"-",F26,"-",G26,) -> Y-P2-ED-1020 | C26: =CONCATENATE(,D26,"-",E26,"-",F26,) -> Y-P2-ED | D26: Y | E26: P2 | F26: ED | G26: =H$6 -> 1020
B27: =CONCATENATE(,D27,"-",E27,"-",F27,"-",G27,) -> Y-P2-ED-1030 | C27: =CONCATENATE(,D27,"-",E27,"-",F27,) -> Y-P2-ED | D27: Y | E27: P2 | F27: ED | G27: =H$7 -> 1030
B28: =CONCATENATE(,D28,"-",E28,"-",F28,"-",G28,) -> Y-P2-ED-1050 | C28: =CONCATENATE(,D28,"-",E28,"-",F28,) -> Y-P2-ED | D28: Y | E28: P2 | F28: ED | G28: =H$8 -> 1050
B29: =CONCATENATE(,D29,"-",E29,"-",F29,"-",G29,) -> Y-P2-A2P-1020 | C29: =CONCATENATE(,D29,"-",E29,"-",F29,) -> Y-P2-A2P | D29: Y | E29: P2 | F29: A2P | G29: =H$6 -> 1020
B30: =CONCATENATE(,D30,"-",E30,"-",F30,"-",G30,) -> Y-P2-A2P-1030 | C30: =CONCATENATE(,D30,"-",E30,"-",F30,) -> Y-P2-A2P | D30: Y | E30: P2 | F30: A2P | G30: =H$7 -> 1030
B31: =CONCATENATE(,D31,"-",E31,"-",F31,"-",G31,) -> Y-P2-A2P-1050 | C31: =CONCATENATE(,D31,"-",E31,"-",F31,) -> Y-P2-A2P | D31: Y | E31: P2 | F31: A2P | G31: =H$8 -> 1050
B32: =CONCATENATE(,D32,"-",E32,"-",G32,) -> R-Ref-1020 | C32: =CONCATENATE(,D32,"-",E32) -> R-Ref | D32: R | E32: Ref | G32: 1020
B33: =CONCATENATE(,D33,"-",E33,"-",G33,) -> R-Ref-1030 | C33: =CONCATENATE(,D33,"-",E33) -> R-Ref | D33: R | E33: Ref | G33: 1030
B34: =CONCATENATE(,D34,"-",E34,"-",G34,) -> R-Ref-1030 | C34: =CONCATENATE(,D34,"-",E34) -> R-Ref | D34: R | E34: Ref | G34: 1030
B35: =CONCATENATE(,D35,"-",E35,"-",F35,"-",G35,) -> R-P1-Raw-1020 | C35: =CONCATENATE(,D35,"-",E35,"-",F35,) -> R-P1-Raw | D35: R | E35: P1 | F35: Raw | G35: =H$6 -> 1020
B36: =CONCATENATE(,D36,"-",E36,"-",F36,"-",G36,) -> R-P1-Raw-1030 | C36: =CONCATENATE(,D36,"-",E36,"-",F36,) -> R-P1-Raw | D36: R | E36: P1 | F36: Raw | G36: =H$7 -> 1030
B37: =CONCATENATE(,D37,"-",E37,"-",F37,"-",G37,) -> R-P1-Raw-1050 | C37: =CONCATENATE(,D37,"-",E37,"-",F37,) -> R-P1-Raw | D37: R | E37: P1 | F37: Raw | G37: =H$8 -> 1050
B38: =CONCATENATE(,D38,"-",E38,"-",F38,"-",G38,) -> R-P1-ED-1020 | C38: =CONCATENATE(,D38,"-",E38,"-",F38,) -> R-P1-ED | D38: R | E38: P1 | F38: ED | G38: =H$6 -> 1020
B39: =CONCATENATE(,D39,"-",E39,"-",F39,"-",G39,) -> R-P1-ED-1030 | C39: =CONCATENATE(,D39,"-",E39,"-",F39,) -> R-P1-ED | D39: R | E39: P1 | F39: ED | G39: =H$7 -> 1030
B40: =CONCATENATE(,D40,"-",E40,"-",F40,"-",G40,) -> R-P1-ED-1050 | C40: =CONCATENATE(,D40,"-",E40,"-",F40,) -> R-P1-ED | D40: R | E40: P1 | F40: ED | G40: =H$8 -> 1050
B41: =CONCATENATE(,D41,"-",E41,"-",F41,"-",G41,) -> R-P2-Raw-1020 | C41: =CONCATENATE(,D41,"-",E41,"-",F41,) -> R-P2-Raw | D41: R | E41: P2 | F41: Raw | G41: =H$6 -> 1020
B42: =CONCATENATE(,D42,"-",E42,"-",F42,"-",G42,) -> R-P2-Raw-1030 | C42: =CONCATENATE(,D42,"-",E42,"-",F42,) -> R-P2-Raw | D42: R | E42: P2 | F42: Raw | G42: =H$7 -> 1030
B43: =CONCATENATE(,D43,"-",E43,"-",F43,"-",G43,) -> R-P2-Raw-1050 | C43: =CONCATENATE(,D43,"-",E43,"-",F43,) -> R-P2-Raw | D43: R | E43: P2 | F43: Raw | G43: =H$8 -> 1050
B44: =CONCATENATE(,D44,"-",E44,"-",F44,"-",G44,) -> R-P2-ED-1020 | C44: =CONCATENATE(,D44,"-",E44,"-",F44,) -> R-P2-ED | D44: R | E44: P2 | F44: ED | G44: =H$6 -> 1020
...

Sheet Mixing
A1: Teglpille blandeopskrift
A3: sample name:
A4: Date:
A5: Made by:
A7: Mængde til fremstilling af en omgang teglpiller a 7 stk
A9: Lynetten | B9: Ly
A10: Avedøre | B10: Av
A11: Elektrodialyse | B11: ED
A12: Ash to Phos | B12: A2P
A14: Production of one batch including 7 discs, 4 g each
C15: Replacement | D15: Clay (g) (dry) | E15: Ash (g) (dry) | F15: Water (g) | G15: Water %
B16: Ref | C16: 0 | D16: 25 | E16: 0 | F16: 6.25 | G16: 20
B17: With ash | C17: 0.3 | D17: 17.5 | E17: 7.5 | F17: 6,25-7,5 | G17: 20-23
A19: Production method, one batch including 7 discs, 4 g each
A20: Mixing
A21: Step 1 | B21: Ad clay to a bowl
A22: Step 2 | B22: Weigh ash on paper and ad to the bowl
A23: Step 3 | B23: Mix ash and clay
A24: Step 4 | B24: Ad demineralized water with a pipette,little at the time, and stir. Ad approx 20-23 %
A25: Step 5 | B25: Mend together with gloved hands, role up and let sit in a sealed bowl for 24 h
A27: Forming
A28: Step 1 | B28: Devide mass in to seven, 4 g each
A29: Step 2 | B29: Place a specimen in steel the die with paper at the bottom and top (for easy release)
A30: Step 3 | B30: Lift the stamp to the top, and let it drop 10 times over the specimen
A31: Step 4 | B31: Release from steel die and weigh
A32: Step 5 | B32: Place in oven, 105 C for 24 h
A34: Forming
A35: Step 1 | B35: Weigh and measure diameter and height
A36: Step 2 | B36: Place in firing oven on designated ceramic plate
A37: Step 3 | B37: Fire at one of three temperatures
A38: Step 4 | B38: Weigh and measure diameter and height
A41: Yellow Clay with Sand 1020 °C | J41: Yellow Clay with Sand 1030 °C | S41: Yellow Clay with Sand 1050 °C
A42: Mix | C42: erstatning | D42: Ler (g) | E42: Aske (g) | F42: Vand (g) | G42: tilsat i alt | H42: Water content % | J42: Pr gang | L42: erstatning | M42: Ler (g) | N42: Aske (g) | O42: Vand (g) | P42: tilsat i alt | Q42: Water content % | S42: Pr gang | U42: erstatning | V42: Ler (g) | W42: Aske (g) | X42: Vand (g) | Y42: tilsat i alt | Z42: Water content %
A43: #4 | B43: Ref | C43: 0 | D43: 25 | E43: 0 | F43: 6.26 | G43: =SUM(F43:F43) -> 6.26 | H43: =G43/(G43+E43+D43)*100 -> 20.025592 | J43: #5 | K43: Ref | L43: 0 | M43: 25 | N43: 0 | O43: 6.28 | P43: =SUM(O43:O43) -> 6.28 | Q43: =P43/(P43+N43+M43)*100 -> 20.076726 | S43: #6 | T43: Ref | U43: 0 | V43: 25 | W43: 0 | X43: 6.44 | Y43: =SUM(X43:X43) -> 6.44 | Z43: =Y43/(Y43+W43+V43)*100 -> 20.483461
A44: #1 | B44: SSA-Av | C44: Raw | D44: 17.5 | E44: 7.5 | F44: 6.68 | G44: =SUM(F44:F44) -> 6.68 | H44: =G44/(G44+E44+D44)*100 -> 21.085859 | J44: #2 | K44: SSA-Av | L44: Raw | M44: 17.5 | N44: 7.5 | O44: 7.53 | P44: =SUM(O44:O44) -> 7.53 | Q44: =P44/(P44+N44+M44)*100 -> 23.147864 | S44: #3 | T44: SSA-Av | U44: Raw | V44: 17.5 | W44: 7.5 | X44: 6.77 | Y44: =SUM(X44:X44) -> 6.77 | Z44: =Y44/(Y44+W44+V44)*100 -> 21.309411
A45: #1 | C45: ED | D45: 17.5 | E45: 7.5 | F45: 7.02 | G45: =SUM(F45:F45) -> 7.02 | H45: =G45/(G45+E45+D45)*100 -> 21.923798 | J45: #2 | L45: ED | M45: 17.5 | N45: 7.5 | O45: 7.25 | P45: =SUM(O45:O45) -> 7.25 | Q45: =P45/(P45+N45+M45)*100 -> 22.48062 | S45: #3 | U45: ED | V45: 17.5 | W45: 7.5 | X45: 6.75 | Y45: =SUM(X45:X45) -> 6.75 | Z45: =Y45/(Y45+W45+V45)*100 -> 21.259843
A46: #7 | B46: SSA-Ly | C46: Raw | D46: 17.5 | E46: 7.5 | F46: 6.66 | G46: =SUM(F46:F46) -> 6.66 | H46: =G46/(G46+E46+D46)*100 -> 21.036008 | J46: #8 | K46: SSA-Ly | L46: Raw | M46: 17.5 | N46: 7.5 | O46: 6.66 | P46: =SUM(O46:O46) -> 6.66 | Q46: =P46/(P46+N46+M46)*100 -> 21.036008 | S46: #9 | T46: SSA-Ly | U46: Raw | V46: 17.5 | W46: 7.5 | X46: 6.68 | Y46: =SUM(X46:X46) -> 6.68 | Z46: =Y46/(Y46+W46+V46)*100 -> 21.085859
A47: #7 | C47: ED | D47: 17.5 | E47: 7.5 | F47: 6.97 | G47: =SUM(F47:F47) -> 6.97 | H47: =G47/(G47+E47+D47)*100 -> 21.801689 | J47: #8 | L47: ED | M47: 17.5 | N47: 7.5 | O47: 7.08 | P47: =SUM(O47:O47) -> 7.08 | Q47: =P47/(P47+N47+M47)*100 -> 22.069825 | S47: #9 | U47: ED | V47: 17.5 | W47: 7.5 | X47: 7.01 | Y47: =SUM(X47:X47) -> 7.01 | Z47: =Y47/(Y47+W47+V47)*100 -> 21.899406
A48: #4 | B48: SSA | C48: A2P | D48: 17.5 | E48: 7.5 | F48: 7.64 | G48: =SUM(F48:F48) -> 7.64 | H48: =G48/(G48+E48+D48)*100 -> 23.406863 | J48: #5 | K48: SSA | L48: A2P | M48: 17.5 | N48: 7.5 | O48: 7.42 | P48: =SUM(O48:O48) -> 7.42 | Q48: =P48/(P48+N48+M48)*100 -> 22.887107 | S48: #6 | T48: SSA | U48: A2P | V48: 17.5 | W48: 7.5 | X48: 7.11 | Y48: =SUM(X48:X48) -> 7.11 | Z48: =Y48/(Y48+W48+V48)*100 -> 22.142635
A51: Red Clay with Sand 1020 °C | J51: Red Clay with Sand 1030 °C | S51: Red Clay with Sand 1050 °C
...

Sheet Water and Burning
A1: Vandindhold og brænding ved 950-1000-1050°C
A3: sample name: | B3: =[1]Mixing!B3 -> 0
A4: Date:
A5: Made by:
A7: 1020 °C | B7: Ref (#4) | H7: A2P (#4)
B8: Prøve | C8: (g) våd | D8: (g) efter 105° | E8: %vandindhold | F8: (g) efter 1020°C | G8: % tab efter 1020 | H8: (g) våd | I8: (g) efter 105° | J8: %vandindhold | K8: (g) efter 1020°C | L8: % tab efter 1020
A9: #0250 | B9: A | C9: 3.8198 | D9: 3.1243 | E9: =((C9-D9)/C9)*100 -> 18.20776 | F9: 2.8395 | G9: =((D9-F9)/D9)*100 -> 9.1156419 | H9: 4.0456 | I9: 3.1456 | J9: =((H9-I9)/H9)*100 -> 22.246391 | K9: 2.9269 | L9: =((I9-K9)/I9)*100 -> 6.9525687
B10: B | C10: 3.9058 | D10: 3.189 | E10: =((C10-D10)/C10)*100 -> 18.352194 | F10: 2.9006 | G10: =((D10-F10)/D10)*100 -> 9.0435873 | H10: 3.9854 | I10: 3.088 | J10: =((H10-I10)/H10)*100 -> 22.517188 | K10: 2.873 | L10: =((I10-K10)/I10)*100 -> 6.9624352
B11: C | C11: 3.8626 | D11: 3.1487 | E11: =((C11-D11)/C11)*100 -> 18.482369 | F11: 2.8621 | G11: =((D11-F11)/D11)*100 -> 9.1021691 | H11: 4.0432 | I11: 3.1254 | J11: =((H11-I11)/H11)*100 -> 22.699842 | K11: 2.9072 | L11: =((I11-K11)/I11)*100 -> 6.9815064
B12: D | C12: 3.9077 | D12: 3.1861 | E12: =((C12-D12)/C12)*100 -> 18.466105 | F12: 2.8963 | G12: =((D12-F12)/D12)*100 -> 9.0957597 | H12: 3.89 | I12: 3.0072 | J12: =((H12-I12)/H12)*100 -> 22.694087 | K12: 2.7992 | L12: =((I12-K12)/I12)*100 -> 6.9167332
B13: E | C13: 3.893 | D13: 3.1643 | E13: =((C13-D13)/C13)*100 -> 18.718212 | F13: 2.8745 | G13: =((D13-F13)/D13)*100 -> 9.1584237 | H13: 3.9528 | I13: 3.0662 | J13: =((H13-I13)/H13)*100 -> 22.42967 | K13: 2.8546 | L13: =((I13-K13)/I13)*100 -> 6.9010502
B14: F | C14: 3.8718 | D14: 3.1498 | E14: =((C14-D14)/C14)*100 -> 18.647657 | F14: 2.863 | G14: =((D14-F14)/D14)*100 -> 9.10534 | H14: 3.922 | I14: 3.0377 | J14: =((H14-I14)/H14)*100 -> 22.54717 | K14: 2.8276 | L14: =((I14-K14)/I14)*100 -> 6.916417
B15: G | C15: 3.9459 | D15: 3.2257 | E15: =((C15-D15)/C15)*100 -> 18.251856 | F15: 2.9276 | G15: =((D15-F15)/D15)*100 -> 9.241405 | H15: 4.0466 | I15: 3.1479 | J15: =((H15-I15)/H15)*100 -> 22.208768 | K15: 2.9283 | L15: =((I15-K15)/I15)*100 -> 6.9760793
A16: #0252 | B16: A | C16: 3.9677 | D16: 3.2176 | E16: =((C16-D16)/C16)*100 -> 18.905159 | F16: 3.0929 | G16: =((D16-F16)/D16)*100 -> 3.8755594 | H16: 4.0863 | I16: 3.1687 | J16: =((H16-I16)/H16)*100 -> 22.455522 | K16: 3.0628 | L16: =((I16-K16)/I16)*100 -> 3.3420646
B17: B | C17: 3.9606 | D17: 3.1966 | E17: =((C17-D17)/C17)*100 -> 19.290007 | F17: 3.0729 | G17: =((D17-F17)/D17)*100 -> 3.8697366 | H17: 3.9847 | I17: 3.0746 | J17: =((H17-I17)/H17)*100 -> 22.839862 | K17: 2.9725 | L17: =((I17-K17)/I17)*100 -> 3.3207572
B18: C | C18: 4.0371 | D18: 3.2625 | E18: =((C18-D18)/C18)*100 -> 19.18704 | F18: 3.1374 | G18: =((D18-F18)/D18)*100 -> 3.8344828 | H18: 3.9867 | I18: 3.0866 | J18: =((H18-I18)/H18)*100 -> 22.57757 | K18: 2.9845 | L18: =((I18-K18)/I18)*100 -> 3.3078468
B19: D | C19: 3.9425 | D19: 3.1817 | E19: =((C19-D19)/C19)*100 -> 19.2974 | F19: 3.0598 | G19: =((D19-F19)/D19)*100 -> 3.8312852 | H19: 3.9644 | I19: 3.0696 | J19: =((H19-I19)/H19)*100 -> 22.570881 | K19: 2.968 | L19: =((I19-K19)/I19)*100 -> 3.3098775
B20: E | C20: 3.807 | D20: 3.0807 | E20: =((C20-D20)/C20)*100 -> 19.078014 | F20: 2.9622 | G20: =((D20-F20)/D20)*100 -> 3.8465284 | H20: 3.9918 | I20: 3.0919 | J20: =((H20-I20)/H20)*100 -> 22.543715 | K20: 2.9886 | L20: =((I20-K20)/I20)*100 -> 3.3409877
B21: F | C21: 3.8374 | D21: 3.1029 | E21: =((C21-D21)/C21)*100 -> 19.140564 | F21: 2.9829 | G21: =((D21-F21)/D21)*100 -> 3.8673499 | H21: 4.006 | I21: 3.1032 | J21: =((H21-I21)/H21)*100 -> 22.536196 | K21: 2.999 | L21: =((I21-K21)/I21)*100 -> 3.3578242
B22: G | C22: 3.8029 | D22: 3.0773 | E22: =((C22-D22)/C22)*100 -> 19.080176 | F22: 2.9574 | G22: =((D22-F22)/D22)*100 -> 3.8962727 | H22: 4.0142 | I22: 3.1155 | J22: =((H22-I22)/H22)*100 -> 22.388023 | K22: 3.0111 | L22: =((I22-K22)/I22)*100 -> 3.350987
A23: 1030 °C | B23: Ref (#5) | H23: A2P (#5)
B24: Prøve | C24: (g) våd | D24: (g) efter 105° | E24: %vandindhold | F24: (g) efter 1030°C | G24: % tab efter 1030 | H24: (g) våd | I24: (g) efter 105° | J24: %vandindhold | K24: (g) efter 1030°C | L24: % tab efter 1030
A25: #0250 | B25: A | C25: 3.8086 | D25: 3.1505 | E25: =((C25-D25)/C25)*100 -> 17.279315 | F25: 2.8712 | G25: =((D25-F25)/D25)*100 -> 8.8652595 | H25: 3.936 | I25: 3.0839 | J25: =((H25-I25)/H25)*100 -> 21.648882 | K25: 2.8712 | L25: =((I25-K25)/I25)*100 -> 6.8971108
B26: B | C26: 3.8583 | D26: 3.1633 | E26: =((C26-D26)/C26)*100 -> 18.013115 | F26: 2.8812 | G26: =((D26-F26)/D26)*100 -> 8.9179022 | H26: 4.0057 | I26: 3.1267 | J26: =((H26-I26)/H26)*100 -> 21.94373 | K26: 2.9086 | L26: =((I26-K26)/I26)*100 -> 6.9754054
B27: C | C27: 3.7949 | D27: 3.1004 | E27: =((C27-D27)/C27)*100 -> 18.300877 | F27: 2.8211 | G27: =((D27-F27)/D27)*100 -> 9.008515 | H27: 3.9571 | I27: 3.0906 | J27: =((H27-I27)/H27)*100 -> 21.897349 | K27: 2.876 | L27: =((I27-K27)/I27)*100 -> 6.9436355
B28: D | C28: 3.838 | D28: 3.1338 | E28: =((C28-D28)/C28)*100 -> 18.348098 | F28: 2.8573 | G28: =((D28-F28)/D28)*100 -> 8.823154 | H28: 3.8779 | I28: 3.0246 | J28: =((H28-I28)/H28)*100 -> 22.004178 | K28: 2.815 | L28: =((I28-K28)/I28)*100 -> 6.929842
B29: E | C29: 3.7719 | D29: 3.071 | E29: =((C29-D29)/C29)*100 -> 18.582147 | F29: 2.7966 | G29: =((D29-F29)/D29)*100 -> 8.9352003 | H29: 3.9741 | I29: 3.1084 | J29: =((H29-I29)/H29)*100 -> 21.783548 | K29: 2.8938 | L29: =((I29-K29)/I29)*100 -> 6.9038734
B30: F | C30: 3.8303 | D30: 3.1318 | E30: =((C30-D30)/C30)*100 -> 18.236169 | F30: 2.8513 | G30: =((D30-F30)/D30)*100 -> 8.9565106 | H30: 3.9526 | I30: 3.101 | J30: =((H30-I30)/H30)*100 -> 21.545312 | K30: 2.8861 | L30: =((I30-K30)/I30)*100 -> 6.9300226
B31: G | C31: 3.7817 | D31: 3.1011 | E31: =((C31-D31)/C31)*100 -> 17.997197 | F31: 2.8238 | G31: =((D31-F31)/D31)*100 -> 8.9419883 | H31: 3.9739 | I31: 3.1045 | J31: =((H31-I31)/H31)*100 -> 21.877752 | K31: 2.8863 | L31: =((I31-K31)/I31)*100 -> 7.028507
A32: #0252 | B32: A | C32: 3.9991 | D32: 3.2509 | E32: =((C32-D32)/C32)*100 -> 18.70921 | F32: 3.1271 | G32: =((D32-F32)/D32)*100 -> 3.8081762 | H32: 4.0272 | I32: 3.1263 | J32: =((H32-I32)/H32)*100 -> 22.370381 | K32: 3.0253 | L32: =((I32-K32)/I32)*100 -> 3.230656
B33: B | C33: 4.015 | D33: 3.2549 | E33: =((C33-D33)/C33)*100 -> 18.931507 | F33: 3.132 | G33: =((D33-F33)/D33)*100 -> 3.7758456 | H33: 4.0278 | I33: 3.1455 | J33: =((H33-I33)/H33)*100 -> 21.905258 | K33: 3.0424 | L33: =((I33-K33)/I33)*100 -> 3.2776983
B34: C | C34: 3.9018 | D34: 3.1642 | E34: =((C34-D34)/C34)*100 -> 18.904096 | F34: 3.0439 | G34: =((D34-F34)/D34)*100 -> 3.8019089 | H34: 4.0653 | I34: 3.1691 | J34: =((H34-I34)/H34)*100 -> 22.045114 | K34: 3.0663 | L34: =((I34-K34)/I34)*100 -> 3.2438232
B35: D | C35: 3.9395 | D35: 3.1942 | E35: =((C35-D35)/C35)*100 -> 18.918644 | F35: 3.0725 | G35: =((D35-F35)/D35)*100 -> 3.8100307 | H35: 3.971 | I35: 3.0835 | J35: =((H35-I35)/H35)*100 -> 22.349534 | K35: 2.9832 | L35: =((I35-K35)/I35)*100 -> 3.2527971
B36: E | C36: 3.8799 | D36: 3.1495 | E36: =((C36-D36)/C36)*100 -> 18.825227 | F36: 3.0296 | G36: =((D36-F36)/D36)*100 -> 3.8069535 | H36: 4.0709 | I36: 3.1708 | J36: =((H36-I36)/H36)*100 -> 22.11059 | K36: 3.0681 | L36: =((I36-K36)/I36)*100 -> 3.2389302
B37: F | C37: 3.9103 | D37: 3.162 | E37: =((C37-D37)/C37)*100 -> 19.136639 | F37: 3.0404 | G37: =((D37-F37)/D37)*100 -> 3.8456673 | H37: 3.9191 | I37: 3.0464 | J37: =((H37-I37)/H37)*100 -> 22.267868 | K37: 2.9472 | L37: =((I37-K37)/I37)*100 -> 3.2563025
B38: G | C38: 3.8557 | D38: 3.137 | E38: =((C38-D38)/C38)*100 -> 18.639936 | F38: 3.0166 | G38: =((D38-F38)/D38)*100 -> 3.8380618 | H38: 4.0433 | I38: 3.1534 | J38: =((H38-I38)/H38)*100 -> 22.00925 | K38: 3.0496 | L38: =((I38-K38)/I38)*100 -> 3.2916852
A39: 1050 °C | B39: Ref (#6) | H39: A2P (#6)
B40: Prøve | C40: (g) våd | D40: (g) efter 105° | E40: %vandindhold | F40: (g) efter 1050°C | G40: % tab efter 1050 | H40: (g) våd | I40: (g) efter 105° | J40: %vandindhold | K40: (g) efter 1050°C | L40: % tab efter 1050
A41: #0250 | B41: A | C41: 3.8888 | D41: 3.1249 | E41: =((C41-D41)/C41)*100 -> 19.643592 | F41: 2.8365 | G41: =((D41-F41)/D41)*100 -> 9.2290953 | H41: 3.992 | I41: 3.1211 | J41: =((H41-I41)/H41)*100 -> 21.816132 | K41: 2.8972 | L41: =((I41-K41)/I41)*100 -> 7.1737528
B42: B | C42: 3.8447 | D42: 3.0877 | E42: =((C42-D42)/C42)*100 -> 19.689443 | F42: 2.8013 | G42: =((D42-F42)/D42)*100 -> 9.2755125 | H42: 3.9755 | I42: 3.1085 | J42: =((H42-I42)/H42)*100 -> 21.808578 | K42: 2.8851 | L42: =((I42-K42)/I42)*100 -> 7.186746
...

Sheet W&B Figures
A1: Vandindhold og brænding ved 950-1000-1050°C
A3: sample name: | B3: =[1]Mixing!B3 -> 0
A4: Date:
A5: Made by:
A7: 1020 °C | B7: Ref (#4) | H7: A2P (#4)
B8: Prøve | C8: (g) våd | D8: (g) efter 105° | E8: %vandindhold | F8: (g) efter 1020°C | G8: % tab efter 1020 | H8: (g) våd | I8: (g) efter 105° | J8: %vandindhold | K8: (g) efter 1020°C | L8: % tab efter 1020
A9: #0250 | B9: A | C9: ='Water and Burning'!C9 -> 3.8198 | D9: ='Water and Burning'!D9 -> 3.1243 | E9: ='Water and Burning'!E9 -> 18.20776 | F9: ='Water and Burning'!F9 -> 2.8395 | G9: ='Water and Burning'!G9 -> 9.1156419 | H9: ='Water and Burning'!H9 -> 4.0456 | I9: ='Water and Burning'!I9 -> 3.1456 | J9: ='Water and Burning'!J9 -> 22.246391 | ... L9: ='Water and Burning'!L9 -> 6.9525687
B10: B | C10: ='Water and Burning'!C10 -> 3.9058 | D10: ='Water and Burning'!D10 -> 3.189 | E10: ='Water and Burning'!E10 -> 18.352194 | F10: ='Water and Burning'!F10 -> 2.9006 | G10: ='Water and Burning'!G10 -> 9.0435873 | H10: ='Water and Burning'!H10 -> 3.9854 | I10: ='Water and Burning'!I10 -> 3.088 | J10: ='Water and Burning'!J10 -> 22.517188 | ... L10: ='Water and Burning'!L10 -> 6.9624352
B11: C | C11: ='Water and Burning'!C11 -> 3.8626 | D11: ='Water and Burning'!D11 -> 3.1487 | E11: ='Water and Burning'!E11 -> 18.482369 | F11: ='Water and Burning'!F11 -> 2.8621 | G11: ='Water and Burning'!G11 -> 9.1021691 | H11: ='Water and Burning'!H11 -> 4.0432 | I11: ='Water and Burning'!I11 -> 3.1254 | J11: ='Water and Burning'!J11 -> 22.699842 | ... L11: ='Water and Burning'!L11 -> 6.9815064
B12: D | C12: ='Water and Burning'!C12 -> 3.9077 | D12: ='Water and Burning'!D12 -> 3.1861 | E12: ='Water and Burning'!E12 -> 18.466105 | F12: ='Water and Burning'!F12 -> 2.8963 | G12: ='Water and Burning'!G12 -> 9.0957597 | H12: ='Water and Burning'!H12 -> 3.89 | I12: ='Water and Burning'!I12 -> 3.0072 | J12: ='Water and Burning'!J12 -> 22.694087 | ... L12: ='Water and Burning'!L12 -> 6.9167332
B13: E | C13: ='Water and Burning'!C13 -> 3.893 | D13: ='Water and Burning'!D13 -> 3.1643 | E13: ='Water and Burning'!E13 -> 18.718212 | F13: ='Water and Burning'!F13 -> 2.8745 | G13: ='Water and Burning'!G13 -> 9.1584237 | H13: ='Water and Burning'!H13 -> 3.9528 | I13: ='Water and Burning'!I13 -> 3.0662 | J13: ='Water and Burning'!J13 -> 22.42967 | ... L13: ='Water and Burning'!L13 -> 6.9010502
B14: F | C14: ='Water and Burning'!C14 -> 3.8718 | D14: ='Water and Burning'!D14 -> 3.1498 | E14: ='Water and Burning'!E14 -> 18.647657 | F14: ='Water and Burning'!F14 -> 2.863 | G14: ='Water and Burning'!G14 -> 9.10534 | H14: ='Water and Burning'!H14 -> 3.922 | I14: ='Water and Burning'!I14 -> 3.0377 | J14: ='Water and Burning'!J14 -> 22.54717 | ... L14: ='Water and Burning'!L14 -> 6.916417
B15: G | C15: ='Water and Burning'!C15 -> 3.9459 | D15: ='Water and Burning'!D15 -> 3.2257 | E15: ='Water and Burning'!E15 -> 18.251856 | F15: ='Water and Burning'!F15 -> 2.9276 | G15: ='Water and Burning'!G15 -> 9.241405 | H15: ='Water and Burning'!H15 -> 4.0466 | I15: ='Water and Burning'!I15 -> 3.1479 | J15: ='Water and Burning'!J15 -> 22.208768 | ... L15: ='Water and Burning'!L15 -> 6.9760793
A16: Average | C16: =AVERAGE(C9:C15) -> 3.8866571 | D16: =AVERAGE(D9:D15) -> 3.1697 | E16: =AVERAGE(E9:E15) -> 18.446593 | F16: =AVERAGE(F9:F15) -> 2.8805143 | G16: =AVERAGE(G9:G15) -> 9.1231895 | H16: =AVERAGE(H9:H15) -> 3.9836571 | I16: =AVERAGE(I9:I15) -> 3.0882857 | J16: =AVERAGE(J9:J15) -> 22.477588 | ... L16: =AVERAGE(L9:L15) -> 6.9438271
A17: STDEV | C17: =STDEV(C9:C15) -> 0.04005945 | D17: =STDEV(D9:D15) -> 0.033428481 | E17: =STDEV(E9:E15) -> 0.19137201 | F17: =STDEV(F9:F15) -> 0.029534919 | G17: =STDEV(G9:G15) -> 0.062078803 | H17: =STDEV(H9:H15) -> 0.064384958 | I17: =STDEV(I9:I15) -> 0.054525114 | J17: =STDEV(J9:J15) -> 0.19608283 | ... L17: =STDEV(L9:L15) -> 0.032139976
A18: #0252 | B18: A | C18: ='Water and Burning'!C16 -> 3.9677 | D18: ='Water and Burning'!D16 -> 3.2176 | E18: ='Water and Burning'!E16 -> 18.905159 | F18: ='Water and Burning'!F16 -> 3.0929 | G18: ='Water and Burning'!G16 -> 3.8755594 | H18: ='Water and Burning'!H16 -> 4.0863 | I18: ='Water and Burning'!I16 -> 3.1687 | J18: ='Water and Burning'!J16 -> 22.455522 | ... L18: ='Water and Burning'!L16 -> 3.3420646
B19: B | C19: ='Water and Burning'!C17 -> 3.9606 | D19: ='Water and Burning'!D17 -> 3.1966 | E19: ='Water and Burning'!E17 -> 19.290007 | F19: ='Water and Burning'!F17 -> 3.0729 | G19: ='Water and Burning'!G17 -> 3.8697366 | H19: ='Water and Burning'!H17 -> 3.9847 | I19: ='Water and Burning'!I17 -> 3.0746 | J19: ='Water and Burning'!J17 -> 22.839862 | ... L19: ='Water and Burning'!L17 -> 3.3207572
B20: C | C20: ='Water and Burning'!C18 -> 4.0371 | D20: ='Water and Burning'!D18 -> 3.2625 | E20: ='Water and Burning'!E18 -> 19.18704 | F20: ='Water and Burning'!F18 -> 3.1374 | G20: ='Water and Burning'!G18 -> 3.8344828 | H20: ='Water and Burning'!H18 -> 3.9867 | I20: ='Water and Burning'!I18 -> 3.0866 | J20: ='Water and Burning'!J18 -> 22.57757 | ... L20: ='Water and Burning'!L18 -> 3.3078468
B21: D | C21: ='Water and Burning'!C19 -> 3.9425 | D21: ='Water and Burning'!D19 -> 3.1817 | E21: ='Water and Burning'!E19 -> 19.2974 | F21: ='Water and Burning'!F19 -> 3.0598 | G21: ='Water and Burning'!G19 -> 3.8312852 | H21: ='Water and Burning'!H19 -> 3.9644 | I21: ='Water and Burning'!I19 -> 3.0696 | J21: ='Water and Burning'!J19 -> 22.570881 | ... L21: ='Water and Burning'!L19 -> 3.3098775
B22: E | C22: ='Water and Burning'!C20 -> 3.807 | D22: ='Water and Burning'!D20 -> 3.0807 | E22: ='Water and Burning'!E20 -> 19.078014 | F22: ='Water and Burning'!F20 -> 2.9622 | G22: ='Water and Burning'!G20 -> 3.8465284 | H22: ='Water and Burning'!H20 -> 3.9918 | I22: ='Water and Burning'!I20 -> 3.0919 | J22: ='Water and Burning'!J20 -> 22.543715 | ... L22: ='Water and Burning'!L20 -> 3.3409877
B23: F | C23: ='Water and Burning'!C21 -> 3.8374 | D23: ='Water and Burning'!D21 -> 3.1029 | E23: ='Water and Burning'!E21 -> 19.140564 | F23: ='Water and Burning'!F21 -> 2.9829 | G23: ='Water and Burning'!G21 -> 3.8673499 | H23: ='Water and Burning'!H21 -> 4.006 | I23: ='Water and Burning'!I21 -> 3.1032 | J23: ='Water and Burning'!J21 -> 22.536196 | ... L23: ='Water and Burning'!L21 -> 3.3578242
B24: G | C24: ='Water and Burning'!C22 -> 3.8029 | D24: ='Water and Burning'!D22 -> 3.0773 | E24: ='Water and Burning'!E22 -> 19.080176 | F24: ='Water and Burning'!F22 -> 2.9574 | G24: ='Water and Burning'!G22 -> 3.8962727 | H24: ='Water and Burning'!H22 -> 4.0142 | I24: ='Water and Burning'!I22 -> 3.1155 | J24: ='Water and Burning'!J22 -> 22.388023 | ... L24: ='Water and Burning'!L22 -> 3.350987
A25: Average | C25: =AVERAGE(C18:C24) -> 3.9078857 | D25: =AVERAGE(D18:D24) -> 3.1599 | E25: =AVERAGE(E18:E24) -> 19.139766 | F25: =AVERAGE(F18:F24) -> 3.0379286 | G25: =AVERAGE(G18:G24) -> 3.8601736 | H25: =AVERAGE(H18:H24) -> 4.0048714 | I25: =AVERAGE(I18:I24) -> 3.1014429 | J25: =AVERAGE(J18:J24) -> 22.558824 | ... L25: =AVERAGE(L18:L24) -> 3.3329064
A26: STDEV | C26: =STDEV(C18:C24) -> 0.091668959 | D26: =STDEV(D18:D24) -> 0.073055436 | E26: =STDEV(E18:E24) -> 0.13666315 | F26: =STDEV(F18:F24) -> 0.070552102 | G26: =STDEV(G18:G24) -> 0.023676895 | H26: =STDEV(H18:H24) -> 0.03929545 | I26: =STDEV(I18:I24) -> 0.033590914 | J26: =STDEV(J18:J24) -> 0.14145917 | ... L26: =STDEV(L18:L24) -> 0.02001208
A27: 1030 °C | B27: Ref (#5) | H27: A2P (#5)
B28: Prøve | C28: (g) våd | D28: (g) efter 105° | E28: %vandindhold | F28: (g) efter 1030°C | G28: % tab efter 1030 | H28: (g) våd | I28: (g) efter 105° | J28: %vandindhold | K28: (g) efter 1030°C | L28: % tab efter 1030
A29: #0250 | B29: A | C29: ='Water and Burning'!C25 -> 3.8086 | D29: ='Water and Burning'!D25 -> 3.1505 | E29: ='Water and Burning'!E25 -> 17.279315 | F29: ='Water and Burning'!F25 -> 2.8712 | G29: ='Water and Burning'!G25 -> 8.8652595 | H29: ='Water and Burning'!H25 -> 3.936 | I29: ='Water and Burning'!I25 -> 3.0839 | J29: ='Water and Burning'!J25 -> 21.648882 | ... L29: ='Water and Burning'!L25 -> 6.8971108
B30: B | C30: ='Water and Burning'!C26 -> 3.8583 | D30: ='Water and Burning'!D26 -> 3.1633 | E30: ='Water and Burning'!E26 -> 18.013115 | F30: ='Water and Burning'!F26 -> 2.8812 | G30: ='Water and Burning'!G26 -> 8.9179022 | H30: ='Water and Burning'!H26 -> 4.0057 | I30: ='Water and Burning'!I26 -> 3.1267 | J30: ='Water and Burning'!J26 -> 21.94373 | ... L30: ='Water and Burning'!L26 -> 6.9754054
B31: C | C31: ='Water and Burning'!C27 -> 3.7949 | D31: ='Water and Burning'!D27 -> 3.1004 | E31: ='Water and Burning'!E27 -> 18.300877 | F31: ='Water and Burning'!F27 -> 2.8211 | G31: ='Water and Burning'!G27 -> 9.008515 | H31: ='Water and Burning'!H27 -> 3.9571 | I31: ='Water and Burning'!I27 -> 3.0906 | J31: ='Water and Burning'!J27 -> 21.897349 | ... L31: ='Water and Burning'!L27 -> 6.9436355
B32: D | C32: ='Water and Burning'!C28 -> 3.838 | D32: ='Water and Burning'!D28 -> 3.1338 | E32: ='Water and Burning'!E28 -> 18.348098 | F32: ='Water and Burning'!F28 -> 2.8573 | G32: ='Water and Burning'!G28 -> 8.823154 | H32: ='Water and Burning'!H28 -> 3.8779 | I32: ='Water and Burning'!I28 -> 3.0246 | J32: ='Water and Burning'!J28 -> 22.004178 | ... L32: ='Water and Burning'!L28 -> 6.929842
B33: E | C33: ='Water and Burning'!C29 -> 3.7719 | D33: ='Water and Burning'!D29 -> 3.071 | E33: ='Water and Burning'!E29 -> 18.582147 | F33: ='Water and Burning'!F29 -> 2.7966 | G33: ='Water and Burning'!G29 -> 8.9352003 | H33: ='Water and Burning'!H29 -> 3.9741 | I33: ='Water and Burning'!I29 -> 3.1084 | J33: ='Water and Burning'!J29 -> 21.783548 | ... L33: ='Water and Burning'!L29 -> 6.9038734
B34: F | C34: ='Water and Burning'!C30 -> 3.8303 | D34: ='Water and Burning'!D30 -> 3.1318 | E34: ='Water and Burning'!E30 -> 18.236169 | F34: ='Water and Burning'!F30 -> 2.8513 | G34: ='Water and Burning'!G30 -> 8.9565106 | H34: ='Water and Burning'!H30 -> 3.9526 | I34: ='Water and Burning'!I30 -> 3.101 | J34: ='Water and Burning'!J30 -> 21.545312 | ... L34: ='Water and Burning'!L30 -> 6.9300226
B35: G | C35: ='Water and Burning'!C31 -> 3.7817 | D35: ='Water and Burning'!D31 -> 3.1011 | E35: ='Water and Burning'!E31 -> 17.997197 | F35: ='Water and Burning'!F31 -> 2.8238 | G35: ='Water and Burning'!G31 -> 8.9419883 | H35: ='Water and Burning'!H31 -> 3.9739 | I35: ='Water and Burning'!I31 -> 3.1045 | J35: ='Water and Burning'!J31 -> 21.877752 | ... L35: ='Water and Burning'!L31 -> 7.028507
A36: Average | C36: =AVERAGE(C29:C35) -> 3.8119571 | D36: =AVERAGE(D29:D35) -> 3.1217 | E36: =AVERAGE(E29:E35) -> 18.108131 | F36: =AVERAGE(F29:F35) -> 2.8432143 | G36: =AVERAGE(G29:G35) -> 8.9212186 | H36: =AVERAGE(H29:H35) -> 3.9539 | I36: =AVERAGE(I29:I35) -> 3.0913857 | J36: =AVERAGE(J29:J35) -> 21.814393 | ... L36: =AVERAGE(L29:L35) -> 6.9440567
A37: STDEV | C37: =STDEV(C29:C35) -> 0.031582266 | D37: =STDEV(D29:D35) -> 0.032292827 | E37: =STDEV(E29:E35) -> 0.41715112 | F37: =STDEV(F29:F35) -> 0.030355528 | G37: =STDEV(G29:G35) -> 0.060899029 | H37: =STDEV(H29:H35) -> 0.039999208 | I37: =STDEV(I29:I35) -> 0.032449932 | J37: =STDEV(J29:J35) -> 0.16552555 | ... L37: =STDEV(L29:L35) -> 0.045336526
A38: #0252 | B38: A | C38: ='Water and Burning'!C32 -> 3.9991 | D38: ='Water and Burning'!D32 -> 3.2509 | E38: ='Water and Burning'!E32 -> 18.70921 | F38: ='Water and Burning'!F32 -> 3.1271 | G38: ='Water and Burning'!G32 -> 3.8081762 | H38: ='Water and Burning'!H32 -> 4.0272 | I38: ='Water and Burning'!I32 -> 3.1263 | J38: ='Water and Burning'!J32 -> 22.370381 | ... L38: ='Water and Burning'!L32 -> 3.230656
B39: B | C39: ='Water and Burning'!C33 -> 4.015 | D39: ='Water and Burning'!D33 -> 3.2549 | E39: ='Water and Burning'!E33 -> 18.931507 | F39: ='Water and Burning'!F33 -> 3.132 | G39: ='Water and Burning'!G33 -> 3.7758456 | H39: ='Water and Burning'!H33 -> 4.0278 | I39: ='Water and Burning'!I33 -> 3.1455 | J39: ='Water and Burning'!J33 -> 21.905258 | ... L39: ='Water and Burning'!L33 -> 3.2776983
B40: C | C40: ='Water and Burning'!C34 -> 3.9018 | D40: ='Water and Burning'!D34 -> 3.1642 | E40: ='Water and Burning'!E34 -> 18.904096 | F40: ='Water and Burning'!F34 -> 3.0439 | G40: ='Water and Burning'!G34 -> 3.8019089 | H40: ='Water and Burning'!H34 -> 4.0653 | I40: ='Water and Burning'!I34 -> 3.1691 | J40: ='Water and Burning'!J34 -> 22.045114 | ... L40: ='Water and Burning'!L34 -> 3.2438232
B41: D | C41: ='Water and Burning'!C35 -> 3.9395 | D41: ='Water and Burning'!D35 -> 3.1942 | E41: ='Water and Burning'!E35 -> 18.918644 | F41: ='Water and Burning'!F35 -> 3.0725 | G41: ='Water and Burning'!G35 -> 3.8100307 | H41: ='Water and Burning'!H35 -> 3.971 | I41: ='Water and Burning'!I35 -> 3.0835 | J41: ='Water and Burning'!J35 -> 22.349534 | ... L41: ='Water and Burning'!L35 -> 3.2527971
B42: E | C42: ='Water and Burning'!C36 -> 3.8799 | D42: ='Water and Burning'!D36 -> 3.1495 | E42: ='Water and Burning'!E36 -> 18.825227 | F42: ='Water and Burning'!F36 -> 3.0296 | G42: ='Water and Burning'!G36 -> 3.8069535 | H42: ='Water and Burning'!H36 -> 4.0709 | I42: ='Water and Burning'!I36 -> 3.1708 | J42: ='Water and Burning'!J36 -> 22.11059 | ... L42: ='Water and Burning'!L36 -> 3.2389302
...

Sheet W&B Figures 2
B3: =[1]Mixing!B3 -> 0
B5: Vandinhold % | E5: STDEV | H5: Loss of mass after firing | K5: STDEV
B6: 1020 | C6: 1030 | D6: 1050 | E6: 1020 | F6: 1030 | G6: 1050 | H6: 1020 | I6: 1030 | J6: 1050 | K6: 1020 | L6: 1030 | M6: 1050 | N6: average | Q6: max | R6: min
A7: Y-Ref | B7: ='W&B Figures'!E16 -> 18.446593 | C7: ='W&B Figures'!E36 -> 18.108131 | D7: ='W&B Figures'!E56 -> 19.701242 | E7: ='W&B Figures'!E17 -> 0.19137201 | F7: ='W&B Figures'!E37 -> 0.41715112 | G7: ='W&B Figures'!E57 -> 0.15841409 | H7: ='W&B Figures'!G16 -> 9.1231895 | I7: ='W&B Figures'!G36 -> 8.9212186 | J7: ='W&B Figures'!G56 -> 9.2894608 | K7: ='W&B Figures'!G17 -> 0.062078803 | L7: ='W&B Figures'!G37 -> 0.060899029 | M7: ='W&B Figures'!G57 -> 0.040432999 | N7: =AVERAGE(H7:J7) -> 9.1112896 | Q7: =MAX(H7:J7) -> 9.2894608 | R7: =MIN(H7:J7) -> 8.9212186
A8: Y-P1-Raw | B8: ='W&B Figures'!E78 -> 19.402666 | C8: ='W&B Figures'!E98 -> 21.027464 | D8: ='W&B Figures'!E118 -> 19.611601 | E8: ='W&B Figures'!E79 -> 0.24698669 | F8: ='W&B Figures'!E99 -> 0.28030377 | G8: ='W&B Figures'!E119 -> 0.3524771 | H8: ='W&B Figures'!G78 -> 6.5542372 | I8: ='W&B Figures'!G98 -> 6.5502141 | J8: ='W&B Figures'!G118 -> 6.8347129 | K8: ='W&B Figures'!G79 -> 0.012315588 | L8: ='W&B Figures'!G99 -> 0.025729479 | M8: ='W&B Figures'!G119 -> 0.12273536 | N8: =AVERAGE(H8:J8) -> 6.646388 | Q8: =MAX(H8:J12) -> 7.279169 | R8: =MIN(H8:J12) -> 6.5502141
A9: Y-P1-ED | B9: ='W&B Figures'!J78 -> 21.072367 | C9: ='W&B Figures'!J98 -> 21.650559 | D9: ='W&B Figures'!J118 -> 20.379121 | E9: ='W&B Figures'!J79 -> 0.30535566 | F9: ='W&B Figures'!J99 -> 0.18025877 | G9: ='W&B Figures'!J119 -> 0.24241124 | H9: ='W&B Figures'!L78 -> 6.9373839 | I9: ='W&B Figures'!L98 -> 7.0467488 | J9: ='W&B Figures'!L118 -> 7.279169 | K9: ='W&B Figures'!L79 -> 0.026267862 | L9: ='W&B Figures'!L99 -> 0.23195397 | M9: ='W&B Figures'!L119 -> 0.04479169 | N9: =AVERAGE(H9:J9) -> 7.0877672
A10: Y-P2-Raw | B10: ='W&B Figures'!E140 -> 19.804261 | C10: ='W&B Figures'!E160 -> 20.041631 | D10: ='W&B Figures'!E180 -> 19.808465 | E10: ='W&B Figures'!E141 -> 0.36183623 | F10: ='W&B Figures'!E161 -> 0.17309335 | G10: ='W&B Figures'!E181 -> 0.17490107 | H10: ='W&B Figures'!G140 -> 6.6909288 | I10: ='W&B Figures'!G160 -> 6.6204161 | J10: ='W&B Figures'!G180 -> 6.6907755 | K10: ='W&B Figures'!G141 -> 0.0090551407 | L10: ='W&B Figures'!G161 -> 0.033515095 | M10: ='W&B Figures'!G181 -> 0.024817095 | N10: =AVERAGE(H10:J10) -> 6.6673735 | Q10: =Q7-Q8 -> 2.0102919 | R10: =Q7-R8 -> 2.7392468
A11: Y-P2-ED | B11: ='W&B Figures'!J140 -> 21.394823 | C11: ='W&B Figures'!J160 -> 21.909682 | D11: ='W&B Figures'!J180 -> 21.420704 | E11: ='W&B Figures'!J141 -> 0.12058988 | F11: ='W&B Figures'!J161 -> 0.18842798 | G11: ='W&B Figures'!J181 -> 0.19692463 | H11: ='W&B Figures'!L140 -> 6.9732606 | I11: ='W&B Figures'!L160 -> 6.8771432 | J11: ='W&B Figures'!L180 -> 6.8810901 | K11: ='W&B Figures'!L141 -> 0.029071745 | L11: ='W&B Figures'!L161 -> 0.038928799 | M11: ='W&B Figures'!L181 -> 0.044620643 | N11: =AVERAGE(H11:J11) -> 6.910498
A12: Y-P2-A2P | B12: ='W&B Figures'!J16 -> 22.477588 | C12: ='W&B Figures'!J36 -> 21.814393 | D12: ='W&B Figures'!J56 -> 21.626469 | E12: ='W&B Figures'!J17 -> 0.19608283 | F12: ='W&B Figures'!J37 -> 0.16552555 | G12: ='W&B Figures'!J57 -> 0.223508 | H12: ='W&B Figures'!L16 -> 6.9438271 | I12: ='W&B Figures'!L36 -> 6.9440567 | J12: ='W&B Figures'!L56 -> 7.1721413 | K12: ='W&B Figures'!L17 -> 0.032139976 | L12: ='W&B Figures'!L37 -> 0.045336526 | M12: ='W&B Figures'!L57 -> 0.019746367 | N12: =AVERAGE(H12:J12) -> 7.0200084
A13: R-Ref | B13: ='W&B Figures'!E25 -> 19.139766 | C13: ='W&B Figures'!E45 -> 18.866466 | D13: ='W&B Figures'!E65 -> 19.925669 | E13: ='W&B Figures'!E26 -> 0.13666315 | F13: ='W&B Figures'!E46 -> 0.16284379 | G13: ='W&B Figures'!E66 -> 0.23524599 | H13: ='W&B Figures'!G25 -> 3.8601736 | I13: ='W&B Figures'!G45 -> 3.8123777 | J13: ='W&B Figures'!G65 -> 3.7759503 | K13: ='W&B Figures'!G26 -> 0.023676895 | L13: ='W&B Figures'!G46 -> 0.023326106 | M13: ='W&B Figures'!G66 -> 0.0087451197 | N13: =AVERAGE(H13:J13) -> 3.8161672 | Q13: =MAX(H13:J13) -> 3.8601736 | R13: =MIN(H13:J13) -> 3.7759503
A14: R-P1-Raw | B14: ='W&B Figures'!E87 -> 20.001524 | C14: ='W&B Figures'!E107 -> 20.91797 | D14: ='W&B Figures'!E127 -> 20.453478 | E14: ='W&B Figures'!E88 -> 0.1806945 | F14: ='W&B Figures'!E108 -> 0.24623101 | G14: ='W&B Figures'!E128 -> 0.12103317 | H14: ='W&B Figures'!G87 -> 3.1010472 | I14: ='W&B Figures'!G107 -> 3.0937416 | J14: ='W&B Figures'!G127 -> 3.2511317 | K14: ='W&B Figures'!G88 -> 0.022301262 | L14: ='W&B Figures'!G108 -> 0.013721388 | M14: ='W&B Figures'!G128 -> 0.015607549 | N14: =AVERAGE(H14:J14) -> 3.1486402 | Q14: =MAX(H14:J18) -> 3.6731045 | R14: =MIN(H14:J18) -> 3.0937416
A15: R-P1-ED | B15: ='W&B Figures'!J87 -> 21.852842 | C15: ='W&B Figures'!J107 -> 21.748573 | D15: ='W&B Figures'!J127 -> 20.954892 | E15: ='W&B Figures'!J88 -> 0.20758062 | F15: ='W&B Figures'!J108 -> 0.091419691 | G15: ='W&B Figures'!J128 -> 0.14609452 | H15: ='W&B Figures'!L87 -> 3.5028861 | I15: ='W&B Figures'!L107 -> 3.4396386 | J15: ='W&B Figures'!L127 -> 3.6731045 | K15: ='W&B Figures'!L88 -> 0.023508014 | L15: ='W&B Figures'!L108 -> 0.020090044 | M15: ='W&B Figures'!L128 -> 0.020124096 | N15: =AVERAGE(H15:J15) -> 3.5385431
A16: R-P2-Raw | B16: ='W&B Figures'!E149 -> 20.789017 | C16: ='W&B Figures'!E169 -> 20.623607 | D16: ='W&B Figures'!E189 -> 20.508361 | E16: ='W&B Figures'!E150 -> 0.16955189 | F16: ='W&B Figures'!E170 -> 0.19672489 | G16: ='W&B Figures'!E190 -> 0.1950543 | H16: ='W&B Figures'!G149 -> 3.1811591 | I16: ='W&B Figures'!G169 -> 3.1919325 | J16: ='W&B Figures'!G189 -> 3.226248 | K16: ='W&B Figures'!G150 -> 0.013283684 | L16: ='W&B Figures'!G170 -> 0.023272235 | M16: ='W&B Figures'!G190 -> 0.029407907 | N16: =AVERAGE(H16:J16) -> 3.1997799 | Q16: =Q13-Q14 -> 0.18706905 | R16: =Q13-R14 -> 0.76643193
A17: R-P2-ED | B17: ='W&B Figures'!J149 -> 21.165692 | C17: ='W&B Figures'!J169 -> 21.316685 | D17: ='W&B Figures'!J189 -> 21.242149 | E17: ='W&B Figures'!J150 -> 0.30535238 | F17: ='W&B Figures'!J170 -> 0.071505224 | G17: ='W&B Figures'!J190 -> 0.18414723 | H17: ='W&B Figures'!L149 -> 3.303279 | I17: ='W&B Figures'!L169 -> 3.3091997 | J17: ='W&B Figures'!L189 -> 3.3191854 | K17: ='W&B Figures'!L150 -> 0.024748617 | L17: ='W&B Figures'!L170 -> 0.02383056 | M17: ='W&B Figures'!L190 -> 0.033672459 | N17: =AVERAGE(H17:J17) -> 3.3105547
A18: R-P2-A2P | B18: ='W&B Figures'!J25 -> 22.558824 | C18: ='W&B Figures'!J45 -> 22.151142 | D18: ='W&B Figures'!J65 -> 22.764289 | E18: ='W&B Figures'!J26 -> 0.14145917 | F18: ='W&B Figures'!J46 -> 0.18005964 | G18: ='W&B Figures'!J66 -> 0.30107126 | H18: ='W&B Figures'!L25 -> 3.3329064 | I18: ='W&B Figures'!L45 -> 3.2559847 | J18: ='W&B Figures'!L65 -> 3.272168 | K18: ='W&B Figures'!L26 -> 0.02001208 | L18: ='W&B Figures'!L46 -> 0.021743058 | M18: ='W&B Figures'!L66 -> 0.020193584 | N18: =AVERAGE(H18:J18) -> 3.2870197

Sheet High and Diameter
A1: High and diameter
A3: sample name: | B3: =[1]Mixing!B3 -> 0
A4: Date:
A5: Made by:
A7: Ref #4 | B7: efter 105°C | L7: Ref #4 | M7: Ref efter 1020°C
B8: Prøve | C8: diameter 1 | D8: diameter 2 | E8: diameter 3 | F8: gennemsnit | G8: højde 1 | H8: højde 2 | I8: højde 3 | J8: gennemsnit | K8: Vol | M8: Prøve | N8: diameter 1 | O8: diameter 2 | P8: diameter 3 | Q8: gennemsnit | R8: højde 1 | S8: højde 2 | T8: højde 3 | U8: gennemsnit | V8: Vol | W8: Shrinkage D [%] | X8: Shrinkage h [%] | Y8: Shrinkage [%]
A9: #0250 | B9: Reference A | C9: 18.66 | D9: 18.55 | E9: 18.61 | F9: =AVERAGE(C9:E9) -> 18.606667 | G9: 5.98 | H9: 5.99 | I9: 6.17 | J9: =AVERAGE(G9:I9) -> 6.0466667 | K9: =PI()*((F9/2)^2)*J9 -> 1644.1562 | L9: #0250 | M9: Reference A | N9: 18.61 | O9: 18.63 | P9: 18.69 | Q9: =AVERAGE(N9:P9) -> 18.643333 | R9: 6.13 | S9: 6.02 | T9: 6 | U9: =AVERAGE(R9:T9) -> 6.05 | V9: =PI()*((Q9/2)^2)*U9 -> 1651.5525 | W9: =((F9-Q9)/F9)*100 -> -0.19706198 | X9: =((J9-U9)/J9)*100 -> -0.055126792 | Y9: =((K9-V9)/K9)*100 -> -0.44985658
B10: Reference B | C10: 18.65 | D10: 18.55 | E10: 18.54 | F10: =AVERAGE(C10:E10) -> 18.58 | G10: 6.11 | H10: 6.09 | I10: 6.06 | J10: =AVERAGE(G10:I10) -> 6.0866667 | K10: =PI()*((F10/2)^2)*J10 -> 1650.2921 | M10: Reference B | N10: 18.56 | O10: 18.72 | P10: 18.62 | Q10: =AVERAGE(N10:P10) -> 18.633333 | R10: 6.1 | S10: 6.14 | T10: 6.16 | U10: =AVERAGE(R10:T10) -> 6.1333333 | V10: =PI()*((Q10/2)^2)*U10 -> 1672.5055 | W10: =((F10-Q10)/F10)*100 -> -0.287047 | X10: =((J10-U10)/J10)*100 -> -0.76670318 | Y10: =((K10-V10)/K10)*100 -> -1.3460291
B11: Reference C | C11: 18.62 | D11: 18.55 | E11: 18.64 | F11: =AVERAGE(C11:E11) -> 18.603333 | G11: 5.97 | H11: 6.14 | I11: 6.02 | J11: =AVERAGE(G11:I11) -> 6.0433333 | K11: =PI()*((F11/2)^2)*J11 -> 1642.6611 | M11: Reference C | N11: 18.6 | O11: 18.55 | P11: 18.55 | Q11: =AVERAGE(N11:P11) -> 18.566667 | R11: 6.05 | S11: 6.01 | T11: 6.04 | U11: =AVERAGE(R11:T11) -> 6.0333333 | V11: =PI()*((Q11/2)^2)*U11 -> 1633.4847 | W11: =((F11-Q11)/F11)*100 -> 0.19709729 | X11: =((J11-U11)/J11)*100 -> 0.16547159 | Y11: =((K11-V11)/K11)*100 -> 0.55862607
B12: Reference D | C12: 18.79 | D12: 18.44 | E12: 18.79 | F12: =AVERAGE(C12:E12) -> 18.673333 | G12: 6.12 | H12: 6.06 | I12: 6.16 | J12: =AVERAGE(G12:I12) -> 6.1133333 | K12: =PI()*((F12/2)^2)*J12 -> 1674.2167 | M12: Reference D | N12: 18.76 | O12: 18.7 | P12: 18.44 | Q12: =AVERAGE(N12:P12) -> 18.633333 | R12: 6.13 | S12: 6.16 | T12: 6.13 | U12: =AVERAGE(R12:T12) -> 6.14 | V12: =PI()*((Q12/2)^2)*U12 -> 1674.3234 | W12: =((F12-Q12)/F12)*100 -> 0.21420921 | X12: =((J12-U12)/J12)*100 -> -0.43620502 | Y12: =((K12-V12)/K12)*100 -> -0.0063786691
B13: Reference E | C13: 18.44 | D13: 18.7 | E13: 18.42 | F13: =AVERAGE(C13:E13) -> 18.52 | G13: 6.39 | H13: 6.19 | I13: 6.08 | J13: =AVERAGE(G13:I13) -> 6.22 | K13: =PI()*((F13/2)^2)*J13 -> 1675.5687 | M13: Reference E | N13: 18.77 | O13: 18.62 | P13: 18.79 | Q13: =AVERAGE(N13:P13) -> 18.726667 | R13: 6.15 | S13: 6.16 | T13: 6.22 | U13: =AVERAGE(R13:T13) -> 6.1766667 | V13: =PI()*((Q13/2)^2)*U13 -> 1701.2377 | W13: =((F13-Q13)/F13)*100 -> -1.1159107 | X13: =((J13-U13)/J13)*100 -> 0.69667738 | Y13: =((K13-V13)/K13)*100 -> -1.5319613
B14: Reference F | C14: 18.57 | D14: 18.61 | E14: 18.56 | F14: =AVERAGE(C14:E14) -> 18.58 | G14: 6.13 | H14: 6.08 | I14: 6.21 | J14: =AVERAGE(G14:I14) -> 6.14 | K14: =PI()*((F14/2)^2)*J14 -> 1664.7525 | M14: Reference F | N14: 18.52 | O14: 18.63 | P14: 18.71 | Q14: =AVERAGE(N14:P14) -> 18.62 | R14: 6.12 | S14: 6.19 | T14: 6.22 | U14: =AVERAGE(R14:T14) -> 6.1766667 | V14: =PI()*((Q14/2)^2)*U14 -> 1681.9125 | W14: =((F14-Q14)/F14)*100 -> -0.21528525 | X14: =((J14-U14)/J14)*100 -> -0.59717698 | Y14: =((K14-V14)/K14)*100 -> -1.030785
B15: Reference G | C15: 18.71 | D15: 18.64 | E15: 18.76 | F15: =AVERAGE(C15:E15) -> 18.703333 | G15: 6.08 | H15: 6.12 | I15: 6.17 | J15: =AVERAGE(G15:I15) -> 6.1233333 | K15: =PI()*((F15/2)^2)*J15 -> 1682.3479 | M15: Reference G | N15: 18.63 | O15: 18.8 | P15: 18.53 | Q15: =AVERAGE(N15:P15) -> 18.653333 | R15: 6.17 | S15: 6.1 | T15: 6.1 | U15: =AVERAGE(R15:T15) -> 6.1233333 | V15: =PI()*((Q15/2)^2)*U15 -> 1673.365 | W15: =((F15-Q15)/F15)*100 -> 0.26733203 | X15: =((J15-U15)/J15)*100 -> 0 | Y15: =((K15-V15)/K15)*100 -> 0.53394939
A16: #0252 | B16: Reference A | C16: 18.5 | D16: 18.54 | E16: 18.5 | F16: =AVERAGE(C16:E16) -> 18.513333 | G16: 6.4 | H16: 6.29 | I16: 6.25 | J16: =AVERAGE(G16:I16) -> 6.3133333 | K16: =PI()*((F16/2)^2)*J16 -> 1699.487 | L16: #0252 | M16: Reference A | N16: 18.53 | O16: 18.62 | P16: 18.5 | Q16: =AVERAGE(N16:P16) -> 18.55 | R16: 6.33 | S16: 6.38 | T16: 6.43 | U16: =AVERAGE(R16:T16) -> 6.38 | V16: =PI()*((Q16/2)^2)*U16 -> 1724.2427 | W16: =((F16-Q16)/F16)*100 -> -0.19805546 | X16: =((J16-U16)/J16)*100 -> -1.0559662 | Y16: =((K16-V16)/K16)*100 -> -1.4566563
B17: Reference B | C17: 18.54 | D17: 18.56 | E17: 18.56 | F17: =AVERAGE(C17:E17) -> 18.553333 | G17: 6.29 | H17: 6.25 | I17: 6.2 | J17: =AVERAGE(G17:I17) -> 6.2466667 | K17: =PI()*((F17/2)^2)*J17 -> 1688.8151 | M17: Reference B | N17: 18.55 | O17: 18.38 | P17: 18.51 | Q17: =AVERAGE(N17:P17) -> 18.48 | R17: 6.37 | S17: 6.38 | T17: 6.32 | U17: =AVERAGE(R17:T17) -> 6.3566667 | V17: =PI()*((Q17/2)^2)*U17 -> 1704.9956 | W17: =((F17-Q17)/F17)*100 -> 0.39525692 | X17: =((J17-U17)/J17)*100 -> -1.7609392 | Y17: =((K17-V17)/K17)*100 -> -0.95809466
B18: Reference C | C18: 18.47 | D18: 18.52 | E18: 18.48 | F18: =AVERAGE(C18:E18) -> 18.49 | G18: 6.36 | H18: 6.66 | I18: 6.5 | J18: =AVERAGE(G18:I18) -> 6.5066667 | K18: =PI()*((F18/2)^2)*J18 -> 1747.1181 | M18: Reference C | N18: 18.55 | O18: 18.52 | P18: 18.47 | Q18: =AVERAGE(N18:P18) -> 18.513333 | R18: 6.61 | S18: 6.62 | T18: 6.52 | U18: =AVERAGE(R18:T18) -> 6.5833333 | V18: =PI()*((Q18/2)^2)*U18 -> 1772.1683 | W18: =((F18-Q18)/F18)*100 -> -0.12619434 | X18: =((J18-U18)/J18)*100 -> -1.1782787 | Y18: =((K18-V18)/K18)*100 -> -1.4338023
B19: Reference D | C19: 18.42 | D19: 18.55 | E19: 18.48 | F19: =AVERAGE(C19:E19) -> 18.483333 | G19: 6.19 | H19: 6.26 | I19: 6.32 | J19: =AVERAGE(G19:I19) -> 6.2566667 | K19: =PI()*((F19/2)^2)*J19 -> 1678.7789 | M19: Reference D | N19: 18.43 | O19: 18.6 | P19: 18.37 | Q19: =AVERAGE(N19:P19) -> 18.466667 | R19: 6.34 | S19: 6.3 | T19: 6.36 | U19: =AVERAGE(R19:T19) -> 6.3333333 | V19: =PI()*((Q19/2)^2)*U19 -> 1696.2867 | W19: =((F19-Q19)/F19)*100 -> 0.090171326 | X19: =((J19-U19)/J19)*100 -> -1.2253596 | Y19: =((K19-V19)/K19)*100 -> -1.0428894
B20: Reference E | C20: 18.38 | D20: 18.62 | E20: 18.41 | F20: =AVERAGE(C20:E20) -> 18.47 | G20: 6.15 | H20: 6.1 | I20: 6.01 | J20: =AVERAGE(G20:I20) -> 6.0866667 | K20: =PI()*((F20/2)^2)*J20 -> 1630.8093 | M20: Reference E | N20: 18.68 | O20: 18.4 | P20: 18.65 | Q20: =AVERAGE(N20:P20) -> 18.576667 | R20: 6.14 | S20: 6.08 | T20: 6.22 | U20: =AVERAGE(R20:T20) -> 6.1466667 | V20: =PI()*((Q20/2)^2)*U20 -> 1665.9621 | W20: =((F20-Q20)/F20)*100 -> -0.57751308 | X20: =((J20-U20)/J20)*100 -> -0.98576123 | Y20: =((K20-V20)/K20)*100 -> -2.1555413
B21: Reference F | C21: 18.48 | D21: 18.56 | E21: 18.45 | F21: =AVERAGE(C21:E21) -> 18.496667 | G21: 6.11 | H21: 6.13 | I21: 6.07 | J21: =AVERAGE(G21:I21) -> 6.1033333 | K21: =PI()*((F21/2)^2)*J21 -> 1640.0002 | M21: Reference F | N21: 18.55 | O21: 18.55 | P21: 18.62 | Q21: =AVERAGE(N21:P21) -> 18.573333 | R21: 6.17 | S21: 6.22 | T21: 6.25 | U21: =AVERAGE(R21:T21) -> 6.2133333 | V21: =PI()*((Q21/2)^2)*U21 -> 1683.4268 | W21: =((F21-Q21)/F21)*100 -> -0.4144891 | X21: =((J21-U21)/J21)*100 -> -1.8022938 | Y21: =((K21-V21)/K21)*100 -> -2.6479616
B22: Reference G | C22: 18.49 | D22: 18.68 | E22: 18.54 | F22: =AVERAGE(C22:E22) -> 18.57 | G22: 6.11 | H22: 6.03 | I22: 6.06 | J22: =AVERAGE(G22:I22) -> 6.0666667 | K22: =PI()*((F22/2)^2)*J22 -> 1643.0993 | M22: Reference G | N22: 18.43 | O22: 18.76 | P22: 18.62 | Q22: =AVERAGE(N22:P22) -> 18.603333 | R22: 6.11 | S22: 6.12 | T22: 6.23 | U22: =AVERAGE(R22:T22) -> 6.1533333 | V22: =PI()*((Q22/2)^2)*U22 -> 1672.5606 | W22: =((F22-Q22)/F22)*100 -> -0.17950099 | X22: =((J22-U22)/J22)*100 -> -1.4285714 | Y22: =((K22-V22)/K22)*100 -> -1.7930288
A23: Ref #5 | B23: efter 105°C | L23: Ref #5 | M23: Ref efter 1030°C
B24: Prøve | C24: diameter 1 | D24: diameter 2 | E24: diameter 3 | F24: gennemsnit | G24: højde 1 | H24: højde 2 | I24: højde 3 | J24: gennemsnit | K24: Vol | M24: Prøve | N24: diameter 1 | O24: diameter 2 | P24: diameter 3 | Q24: gennemsnit | R24: højde 1 | S24: højde 2 | T24: højde 3 | U24: gennemsnit | V24: Vol | W24: Shrinkage D [%] | X24: Shrinkage h [%] | Y24: Shrinkage [%]
A25: #0250 | B25: Reference A | C25: 18.71 | D25: 18.6 | E25: 18.61 | F25: =AVERAGE(C25:E25) -> 18.64 | G25: 6.03 | H25: 6.06 | I25: 6.02 | J25: =AVERAGE(G25:I25) -> 6.0366667 | K25: =PI()*((F25/2)^2)*J25 -> 1647.3235 | L25: #0250 | M25: Reference A | N25: 18.57 | O25: 18.71 | P25: 18.56 | Q25: =AVERAGE(N25:P25) -> 18.613333 | R25: 6.06 | S25: 6.05 | T25: 6.11 | U25: =AVERAGE(R25:T25) -> 6.0733333 | V25: =PI()*((Q25/2)^2)*U25 -> 1652.5907 | W25: =((F25-Q25)/F25)*100 -> 0.14306152 | X25: =((J25-U25)/J25)*100 -> -0.60739923 | Y25: =((K25-V25)/K25)*100 -> -0.31974419
B26: Reference B | C26: 18.51 | D26: 18.49 | E26: 18.49 | F26: =AVERAGE(C26:E26) -> 18.496667 | G26: 6.14 | H26: 6.24 | I26: 6.13 | J26: =AVERAGE(G26:I26) -> 6.17 | K26: =PI()*((F26/2)^2)*J26 -> 1657.9139 | M26: Reference B | N26: 18.63 | O26: 18.51 | P26: 18.61 | Q26: =AVERAGE(N26:P26) -> 18.583333 | R26: 6.08 | S26: 6.24 | T26: 6.1 | U26: =AVERAGE(R26:T26) -> 6.14 | V26: =PI()*((Q26/2)^2)*U26 -> 1665.3499 | W26: =((F26-Q26)/F26)*100 -> -0.46855289 | X26: =((J26-U26)/J26)*100 -> 0.48622366 | Y26: =((K26-V26)/K26)*100 -> -0.44851044
B27: Reference C | C27: 18.69 | D27: 18.6 | E27: 18.52 | F27: =AVERAGE(C27:E27) -> 18.603333 | G27: 6.01 | H27: 5.96 | I27: 6.07 | J27: =AVERAGE(G27:I27) -> 6.0133333 | K27: =PI()*((F27/2)^2)*J27 -> 1634.5067 | M27: Reference C | N27: 18.75 | O27: 18.42 | P27: 18.71 | Q27: =AVERAGE(N27:P27) -> 18.626667 | R27: 5.96 | S27: 6.07 | T27: 6 | U27: =AVERAGE(R27:T27) -> 6.01 | V27: =PI()*((Q27/2)^2)*U27 -> 1637.7011 | W27: =((F27-Q27)/F27)*100 -> -0.12542555 | X27: =((J27-U27)/J27)*100 -> 0.055432373 | Y27: =((K27-V27)/K27)*100 -> -0.19543691
B28: Reference D | C28: 18.63 | D28: 18.64 | E28: 18.53 | F28: =AVERAGE(C28:E28) -> 18.6 | G28: 6.12 | H28: 6.11 | I28: 6.06 | J28: =AVERAGE(G28:I28) -> 6.0966667 | K28: =PI()*((F28/2)^2)*J28 -> 1656.564 | M28: Reference D | N28: 18.77 | O28: 18.59 | P28: 18.68 | Q28: =AVERAGE(N28:P28) -> 18.68 | R28: 6.09 | S28: 6.16 | T28: 6.06 | U28: =AVERAGE(R28:T28) -> 6.1033333 | V28: =PI()*((Q28/2)^2)*U28 -> 1672.6717 | W28: =((F28-Q28)/F28)*100 -> -0.43010753 | X28: =((J28-U28)/J28)*100 -> -0.10934937 | Y28: =((K28-V28)/K28)*100 -> -0.97235701
B29: Reference E | C29: 18.52 | D29: 18.5 | E29: 18.48 | F29: =AVERAGE(C29:E29) -> 18.5 | G29: 6.28 | H29: 6.12 | I29: 6.24 | J29: =AVERAGE(G29:I29) -> 6.2133333 | K29: =PI()*((F29/2)^2)*J29 -> 1670.1597 | M29: Reference E | N29: 18.63 | O29: 18.62 | P29: 18.43 | Q29: =AVERAGE(N29:P29) -> 18.56 | R29: 6.12 | S29: 6.09 | T29: 6.1 | U29: =AVERAGE(R29:T29) -> 6.1033333 | V29: =PI()*((Q29/2)^2)*U29 -> 1651.2503 | W29: =((F29-Q29)/F29)*100 -> -0.32432432 | X29: =((J29-U29)/J29)*100 -> 1.7703863 | Y29: =((K29-V29)/K29)*100 -> 1.132188
B30: Reference F | C30: 18.56 | D30: 18.73 | E30: 18.45 | F30: =AVERAGE(C30:E30) -> 18.58 | G30: 6.03 | H30: 6.03 | I30: 6.03 | J30: =AVERAGE(G30:I30) -> 6.03 | K30: =PI()*((F30/2)^2)*J30 -> 1634.9279 | M30: Reference F | N30: 18.69 | O30: 18.44 | P30: 18.79 | Q30: =AVERAGE(N30:P30) -> 18.64 | R30: 6.07 | S30: 6.05 | T30: 6.08 | U30: =AVERAGE(R30:T30) -> 6.0666667 | V30: =PI()*((Q30/2)^2)*U30 -> 1655.5101 | W30: =((F30-Q30)/F30)*100 -> -0.32292788 | X30: =((J30-U30)/J30)*100 -> -0.60807076 | Y30: =((K30-V30)/K30)*100 -> -1.2589029
B31: Reference G | C31: 18.58 | D31: 19.29 | E31: 19.46 | F31: =AVERAGE(C31:E31) -> 19.11 | G31: 6.01 | H31: 6.08 | I31: 5.89 | J31: =AVERAGE(G31:I31) -> 5.9933333 | K31: =PI()*((F31/2)^2)*J31 -> 1719.0151 | M31: Reference G | N31: 18.67 | O31: 19.41 | P31: 18.61 | Q31: =AVERAGE(N31:P31) -> 18.896667 | R31: 5.97 | S31: 6.01 | T31: 6.03 | U31: =AVERAGE(R31:T31) -> 6.0033333 | V31: =PI()*((Q31/2)^2)*U31 -> 1683.6536 | W31: =((F31-Q31)/F31)*100 -> 1.116344 | X31: =((J31-U31)/J31)*100 -> -0.16685206 | Y31: =((K31-V31)/K31)*100 -> 2.0570781
A32: #0252 | B32: Reference A | C32: 18.33 | D32: 18.45 | E32: 18.47 | F32: =AVERAGE(C32:E32) -> 18.416667 | G32: 6.34 | H32: 6.64 | I32: 6.44 | J32: =AVERAGE(G32:I32) -> 6.4733333 | K32: =PI()*((F32/2)^2)*J32 -> 1724.4075 | L32: #0252 | M32: Reference A | N32: 18.39 | O32: 18.42 | P32: 18.54 | Q32: =AVERAGE(N32:P32) -> 18.45 | R32: 6.54 | S32: 6.53 | T32: 6.52 | U32: =AVERAGE(R32:T32) -> 6.53 | V32: =PI()*((Q32/2)^2)*U32 -> 1745.8053 | W32: =((F32-Q32)/F32)*100 -> -0.18099548 | X32: =((J32-U32)/J32)*100 -> -0.8753862 | Y32: =((K32-V32)/K32)*100 -> -1.2408764
B33: Reference B | C33: 18.49 | D33: 18.55 | E33: 18.59 | F33: =AVERAGE(C33:E33) -> 18.543333 | G33: 6.33 | H33: 6.37 | I33: 6.34 | J33: =AVERAGE(G33:I33) -> 6.3466667 | K33: =PI()*((F33/2)^2)*J33 -> 1714.0014 | M33: Reference B | N33: 18.52 | O33: 18.48 | P33: 18.47 | Q33: =AVERAGE(N33:P33) -> 18.49 | R33: 6.51 | S33: 6.48 | T33: 6.46 | U33: =AVERAGE(R33:T33) -> 6.4833333 | V33: =PI()*((Q33/2)^2)*U33 -> 1740.8528 | W33: =((F33-Q33)/F33)*100 -> 0.2876146 | X33: =((J33-U33)/J33)*100 -> -2.1533613 | Y33: =((K33-V33)/K33)*100 -> -1.5665904
B34: Reference C | C34: 18.47 | D34: 18.48 | E34: 18.49 | F34: =AVERAGE(C34:E34) -> 18.48 | G34: 6.31 | H34: 6.17 | I34: 6.2 | J34: =AVERAGE(G34:I34) -> 6.2266667 | K34: =PI()*((F34/2)^2)*J34 -> 1670.1268 | M34: Reference C | N34: 18.74 | O34: 18.34 | P34: 18.48 | Q34: =AVERAGE(N34:P34) -> 18.52 | R34: 6.18 | S34: 6.35 | T34: 6.3 | U34: =AVERAGE(R34:T34) -> 6.2766667 | V34: =PI()*((Q34/2)^2)*U34 -> 1690.8338 | W34: =((F34-Q34)/F34)*100 -> -0.21645022 | X34: =((J34-U34)/J34)*100 -> -0.80299786 | Y34: =((K34-V34)/K34)*100 -> -1.2398467
B35: Reference D | C35: 18.54 | D35: 18.6 | E35: 18.53 | F35: =AVERAGE(C35:E35) -> 18.556667 | G35: 6.27 | H35: 6.26 | I35: 6.24 | J35: =AVERAGE(G35:I35) -> 6.2566667 | K35: =PI()*((F35/2)^2)*J35 -> 1692.1265 | M35: Reference D | N35: 18.57 | O35: 18.47 | P35: 18.48 | Q35: =AVERAGE(N35:P35) -> 18.506667 | R35: 6.35 | S35: 6.42 | T35: 6.33 | U35: =AVERAGE(R35:T35) -> 6.3666667 | V35: =PI()*((Q35/2)^2)*U35 -> 1712.6097 | W35: =((F35-Q35)/F35)*100 -> 0.26944494 | X35: =((J35-U35)/J35)*100 -> -1.7581247 | Y35: =((K35-V35)/K35)*100 -> -1.2104992
B36: Reference E | C36: 18.53 | D36: 18.61 | E36: 18.58 | F36: =AVERAGE(C36:E36) -> 18.573333 | G36: 6.21 | H36: 6.12 | I36: 6.25 | J36: =AVERAGE(G36:I36) -> 6.1933333 | K36: =PI()*((F36/2)^2)*J36 -> 1678.0081 | M36: Reference E | N36: 18.5 | O36: 18.57 | P36: 18.64 | Q36: =AVERAGE(N36:P36) -> 18.57 | R36: 6.21 | S36: 6.25 | T36: 6.3 | U36: =AVERAGE(R36:T36) -> 6.2533333 | V36: =PI()*((Q36/2)^2)*U36 -> 1693.6562 | W36: =((F36-Q36)/F36)*100 -> 0.017946877 | X36: =((J36-U36)/J36)*100 -> -0.96878364 | Y36: =((K36-V36)/K36)*100 -> -0.9325454
B37: Reference F | C37: 18.62 | D37: 18.59 | E37: 18.55 | F37: =AVERAGE(C37:E37) -> 18.586667 | G37: 6.23 | H37: 6.21 | I37: 6.29 | J37: =AVERAGE(G37:I37) -> 6.2433333 | K37: =PI()*((F37/2)^2)*J37 -> 1693.9845 | M37: Reference F | N37: 18.45 | O37: 18.67 | P37: 18.67 | Q37: =AVERAGE(N37:P37) -> 18.596667 | R37: 6.28 | S37: 6.38 | T37: 6.35 | U37: =AVERAGE(R37:T37) -> 6.3366667 | V37: =PI()*((Q37/2)^2)*U37 -> 1721.1589 | W37: =((F37-Q37)/F37)*100 -> -0.053802009 | X37: =((J37-U37)/J37)*100 -> -1.4949279 | Y37: =((K37-V37)/K37)*100 -> -1.6041699
B38: Reference G | C38: 18.75 | D38: 18.61 | E38: 18.82 | F38: =AVERAGE(C38:E38) -> 18.726667 | G38: 6.16 | H38: 6.17 | I38: 6.12 | J38: =AVERAGE(G38:I38) -> 6.15 | K38: =PI()*((F38/2)^2)*J38 -> 1693.8929 | M38: Reference G | N38: 18.62 | O38: 18.53 | P38: 18.74 | Q38: =AVERAGE(N38:P38) -> 18.63 | R38: 6.28 | S38: 6.25 | T38: 6.26 | U38: =AVERAGE(R38:T38) -> 6.2633333 | V38: =PI()*((Q38/2)^2)*U38 -> 1707.3443 | W38: =((F38-Q38)/F38)*100 -> 0.51619794 | X38: =((J38-U38)/J38)*100 -> -1.8428184 | Y38: =((K38-V38)/K38)*100 -> -0.79411108
A39: Ref #6 | B39: efter 105°C | L39: Ref #6 | M39: Ref efter 1050°C
B40: Prøve | C40: diameter 1 | D40: diameter 2 | E40: diameter 3 | F40: gennemsnit | G40: højde 1 | H40: højde 2 | I40: højde 3 | J40: gennemsnit | K40: Vol | M40: Prøve | N40: diameter 1 | O40: diameter 2 | P40: diameter 3 | Q40: gennemsnit | R40: højde 1 | S40: højde 2 | T40: højde 3 | U40: gennemsnit | V40: Vol | W40: Shrinkage D [%] | X40: Shrinkage h [%] | Y40: Shrinkage [%]
A41: #0250 | B41: Reference A | C41: 18.59 | D41: 18.4 | E41: 18.59 | F41: =AVERAGE(C41:E41) -> 18.526667 | G41: 6.19 | H41: 6.21 | I41: 6.22 | J41: =AVERAGE(G41:I41) -> 6.2066667 | K41: =PI()*((F41/2)^2)*J41 -> 1673.1808 | L41: #0250 | M41: Reference A | N41: 18.43 | O41: 18.56 | P41: 18.61 | Q41: =AVERAGE(N41:P41) -> 18.533333 | R41: 6.28 | S41: 6.17 | T41: 6.12 | U41: =AVERAGE(R41:T41) -> 6.19 | V41: =PI()*((Q41/2)^2)*U41 -> 1669.889 | W41: =((F41-Q41)/F41)*100 -> -0.035984167 | X41: =((J41-U41)/J41)*100 -> 0.26852846 | Y41: =((K41-V41)/K41)*100 -> 0.19674047
B42: Reference B | C42: 18.43 | D42: 18.63 | E42: 18.57 | F42: =AVERAGE(C42:E42) -> 18.543333 | G42: 6.08 | H42: 6.23 | I42: 6.27 | J42: =AVERAGE(G42:I42) -> 6.1933333 | K42: =PI()*((F42/2)^2)*J42 -> 1672.5917 | M42: Reference B | N42: 18.44 | O42: 18.49 | P42: 18.38 | Q42: =AVERAGE(N42:P42) -> 18.436667 | R42: 6.28 | S42: 6.29 | T42: 6.04 | U42: =AVERAGE(R42:T42) -> 6.2033333 | V42: =PI()*((Q42/2)^2)*U42 -> 1656.0743 | W42: =((F42-Q42)/F42)*100 -> 0.57522919 | X42: =((J42-U42)/J42)*100 -> -0.16146394 | Y42: =((K42-V42)/K42)*100 -> 0.98753779
...

Sheet H&D Figures
O6: Average fired D | P6: =AVERAGE(F9:F15,F18:F24,F29:F35,F38:F44,F49:F55,F58:F64,F72:F78,F81:F87,F92:F98,F101:F107,F112:F118,F121:F127,F134:F140,F143:F149,F154:F160,F163:F169,F174:F180,F183:F189,F196:F202,F205:F211,F216:F222,F226:F231,F236:F242,F245:F251,T183:T189,T174:T180,T163:T169,T154:T160,T143:T149,T134:T140,T121:T127,T112:T118,T92:T98,T101:T107,T72:T78,T81:T87) -> 18.16243 | Q6: stdev | R6: =STDEV(F9:F15,F18:F24,F29:F35,F38:F44,F49:F55,F58:F64,F72:F78,F81:F87,F92:F98,F101:F107,F112:F118,F121:F127,F134:F140,F143:F149,F154:F160,F163:F169,F174:F180,F183:F189,F196:F202,F205:F211,F216:F222,F226:F231,F236:F242,F245:F251,T183:T189,T174:T180,T163:T169,T154:T160,T143:T149,T134:T140,T121:T127,T112:T118,T92:T98,T101:T107,T72:T78,T81:T87) -> 0.48609453 | S6: mm2
A7: ='High and Diameter'!A7 -> Ref #4 | C7: efter 105°C | F7: efter 1020°C
B8: Prøve | C8: Diameter | D8: Height | E8: ='High and Diameter'!K8 -> Vol | F8: Diameter | G8: Height | H8: ='High and Diameter'!V8 -> Vol | I8: ='High and Diameter'!W8 -> Shrinkage D [%] | J8: ='High and Diameter'!X8 -> Shrinkage h [%] | K8: ='High and Diameter'!Y8 -> Shrinkage [%] | L8: Drying shrinkage D[%]
A9: Y-Ref | B9: A | C9: ='High and Diameter'!F9 -> 18.606667 | D9: ='High and Diameter'!J9 -> 6.0466667 | E9: ='High and Diameter'!K9 -> 1644.1562 | F9: ='High and Diameter'!Q9 -> 18.643333 | G9: ='High and Diameter'!U9 -> 6.05 | H9: ='High and Diameter'!V9 -> 1651.5525 | I9: ='High and Diameter'!W9 -> -0.19706198 | J9: ='High and Diameter'!X9 -> -0.055126792 | K9: ='High and Diameter'!Y9 -> -0.44985658 | L9: =(20-C9)/20*100 -> 6.9666667 | O9: A
B10: B | C10: ='High and Diameter'!F10 -> 18.58 | D10: ='High and Diameter'!J10 -> 6.0866667 | E10: ='High and Diameter'!K10 -> 1650.2921 | F10: ='High and Diameter'!Q10 -> 18.633333 | G10: ='High and Diameter'!U10 -> 6.1333333 | H10: ='High and Diameter'!V10 -> 1672.5055 | I10: ='High and Diameter'!W10 -> -0.287047 | J10: ='High and Diameter'!X10 -> -0.76670318 | K10: ='High and Diameter'!Y10 -> -1.3460291 | L10: =(20-C10)/20*100 -> 7.1 | O10: B
B11: C | C11: ='High and Diameter'!F11 -> 18.603333 | D11: ='High and Diameter'!J11 -> 6.0433333 | E11: ='High and Diameter'!K11 -> 1642.6611 | F11: ='High and Diameter'!Q11 -> 18.566667 | G11: ='High and Diameter'!U11 -> 6.0333333 | H11: ='High and Diameter'!V11 -> 1633.4847 | I11: ='High and Diameter'!W11 -> 0.19709729 | J11: ='High and Diameter'!X11 -> 0.16547159 | K11: ='High and Diameter'!Y11 -> 0.55862607 | L11: =(20-C11)/20*100 -> 6.9833333 | O11: C
